<?xml version="1.0" ?>

<sdf version="1.6">
  <world name="visualize_lidar_world">
    
    <gui fullscreen="0">
      <plugin filename="GzScene3D" name="3D View">
        <camera_pose>10 0 6 0 0.5 3.14</camera_pose>
        <ignition-gui>
          <title>3D View</title>
          <property type="bool" key="showTitleBar">false</property>
          <property type="string" key="state">docked</property>
        </ignition-gui>
      </plugin>

      <plugin filename="SwitchPanel" name="iginition_plugin_lecture::SwitchPanel">
        <forward_speed>0.3</forward_speed>
        <reverse_speed>-0.1</reverse_speed>
        <ignition-gui>
          <title>SwitchPanel</title>
          <property type="bool" key="showTitleBar">true</property>
          <property type="string" key="state">docked</property>
          <property key="resizable" type="bool">true</property>
        </ignition-gui>
      </plugin>

      <plugin filename="Teleop" name="ignition::gui::plugins::Teleop">
        <topic>/cmd_vel</topic>
        <ignition-gui>
          <property type="bool" key="showTitleBar">true</property>
          <property type="string" key="state">docked</property>
          <property key="resizable" type="bool">true</property>
        </ignition-gui>
      </plugin>
    </gui>

    <physics name="1ms" type="ignored">
      <max_step_size>0.001</max_step_size>
      <real_time_factor>1.0</real_time_factor>
    </physics>
    <plugin
      filename="libignition-gazebo-physics-system.so"
      name="ignition::gazebo::systems::Physics">
    </plugin>
    <plugin
      filename="libignition-gazebo-sensors-system.so"
      name="ignition::gazebo::systems::Sensors">
      <render_engine>ogre2</render_engine>
    </plugin>
    <plugin
      filename="libignition-gazebo-scene-broadcaster-system.so"
      name="ignition::gazebo::systems::SceneBroadcaster">
    </plugin>

    <light name="sun" type="directional">
      <cast_shadows>true</cast_shadows>
      <pose>0 0 10 0 0 0</pose>
      <diffuse>0.8 0.8 0.8 1</diffuse>
      <specular>0.2 0.2 0.2 1</specular>
      <attenuation>
        <range>1000</range>
        <constant>0.9</constant>
        <linear>0.01</linear>
        <quadratic>0.001</quadratic>
      </attenuation>
      <direction>-0.5 0.1 -0.9</direction>
    </light>

    <model name="ground_plane">
      <static>true</static>
      <pose>0 0 0 0 0 0</pose>
      <link name="link">
        <collision name="collision">
          <geometry>
            <box>
              <size>20 20 0.1</size>
            </box>
          </geometry>
        </collision>
        <visual name="visual">
          <geometry>
            <box>
              <size>20 20 0.1</size>
            </box>
          </geometry>
          <material>
            <ambient>0.8 0.8 0.8 1</ambient>
            <diffuse>0.8 0.8 0.8 1</diffuse>
            <specular>0.8 0.8 0.8 1</specular>
          </material>
        </visual>
      </link>
    </model>

    <model name="box">
      <plugin filename="libRotateAxis.so" name="iginition_plugin_lecture::RotateAxis">
        <target_joint>arm_joint</target_joint>
      </plugin>

      <pose>0 -1 0.5 0 0 0</pose>
      <link name="box_link">
        <inertial>
          <inertia>
            <ixx>1</ixx>
            <ixy>0</ixy>
            <ixz>0</ixz>
            <iyy>1</iyy>
            <iyz>0</iyz>
            <izz>1</izz>
          </inertia>
          <mass>1.0</mass>
        </inertial>
        <collision name="box_collision">
          <geometry>
            <box>
              <size>1 1 1</size>
            </box>
          </geometry>
        </collision>

        <visual name="box_visual">
          <geometry>
            <box>
              <size>1 1 1</size>
            </box>
          </geometry>
          <material>
            <ambient>1 0 0 1</ambient>
            <diffuse>1 0 0 1</diffuse>
            <specular>1 0 0 1</specular>
          </material>
        </visual>
      </link>

      <joint name="arm_joint" type="revolute">
        <pose>0 0 -0.5 0 0 0</pose>
        <parent>box_link</parent>
        <child>arm_link</child>
        <axis>
          <xyz>1 0 0</xyz>
          <limit>
            <upper>1.57</upper>
            <lower>-1.57</lower>
            <effort>1.0</effort>
          </limit>
        </axis>
      </joint>

      <link name="arm_link">
        <pose>0 0 1.2 0 0 0</pose>
        <inertial>
          <inertia>
            <ixx>0.008</ixx>
            <ixy>0</ixy>
            <ixz>0</ixz>
            <iyy>0.008</iyy>
            <iyz>0</iyz>
            <izz>0.00016</izz>
          </inertia>
          <mass>0.1</mass>
        </inertial>
        <collision name="arm_collision">
          <geometry>
            <box>
              <size>0.1 0.1 1</size>
            </box>
          </geometry>
        </collision>

        <visual name="arm_visual">
          <geometry>
            <box>
              <size>0.1 0.1 1</size>
            </box>
          </geometry>
          <material>
            <ambient>1 0 0 1</ambient>
            <diffuse>1 0 0 1</diffuse>
            <specular>1 0 0 1</specular>
          </material>
        </visual>
      </link>
    </model>

    <include>
      <pose>5 0 0 0 0 1.57</pose>
      <uri>https://fuel.gazebosim.org/1.0/nate/models/Valve</uri>
    </include>

    <include>
      <uri>package://ignition_lecture/models/my_box</uri>
      <pose>0 2 0 0 0 0</pose>
    </include>

  </world>
</sdf>
